Workbook

Sheet Faktoren ProdReorganisation
B1: Kostenfaktoren zur Prozesskostenoptimierung bei Produktions‑Umstrukturierungen
B2: Kosten- Bewertungsfaktor | E2: Kosten Verdichten | F2: Status | G2: Kosten Fechern 3S | H2: Kosten Fechern 2S | I2: Verantwortlich | J2: Kommentar | K2: Faktor
B3: 1. Personalkosten
C4: 1.1 Direkte Personalkosten
D5: Löhne und Gehälter | E5: 3 | G5: 3 | H5: 3 | K5: 2
D6: Zuschläge (Schicht, Überstunden, Erschwerniszulagen) | E6: 3 | G6: 3 | H6: 4 | K6: 2
D7: Kosten Wochenendarbeit | E7: 2 | G7: 3 | H7: 2 | I7: Andreas | K7: 2
D8: Kosten für Personalabbau (Abfindungen, Sozialpläne) | E8: 3 | G8: 3 | H8: 3 | K8: 2
C9: 1.2 Indirekte Personalkosten | K9: 2
D10: Löhne und Gehälter | E10: 3 | G10: 3 | H10: 4 | K10: 2
D11: Kosten für Schulungen und Qualifizierungen (z. B. neue Anlagen) | E11: 3 | G11: 3 | H11: 3 | K11: 2
D12: Kosten durch temporäre Produktivitätsverluste während der Lernkurve | E12: 3 | G12: 3 | H12: 3 | K12: 2
D13: Kosten durch Versetzungen oder Umplatzierungen | E13: 4 | G13: 3 | H13: 3 | I13: Andreas | K13: 2
D14: Kosten für Personalabbau (Abfindungen, Sozialpläne) | E14: 3 | G14: 3 | H14: 2 | K14: 2
B15: 2. Material- und Beschaffungskosten | K15: 1
C16: Eine Umstrukturierung hat häufig direkten Einfluss auf Materialflüsse und Beschaffung. | E16: 3 | G16: 3 | H16: 3 | K16: 1
C17: Auswirkungen eigener Prozessänderungen auf Materialverbrauch | E17: 4 | G17: 3 | H17: 2 | I17: Andreas | K17: 1
C18: Kosten der Materialbereitstellung (Intralogistik, Kitting) | E18: 5 | G18: 3 | H18: 3 | I18: Andreas | K18: 1
C19: Bestandskosten (Lagerung, Umlaufbestände, Sicherheitsbestände) | E19: 2 | G19: 3 | H19: 3 | I19: Andreas | K19: 1
C20: Transportkosten intern & extern | E20: 3 | G20: 3 | H20: 3 | K20: 1
C21: Ausschuss- und Nacharbeitskosten | E21: 3 | G21: 3 | H21: 2 | K21: 1
B22: 3. Maschinen- und Anlagenkosten | K22: 1
C23: 3.1 Investitionskosten | K23: 1
D24: Kauf neuer Maschinen oder Anlagen | E24: 3 | G24: 3 | H24: 3 | K24: 2
D25: Umbaukosten bestehender Anlagen | E25: 3 | G25: 3 | H25: 3 | K25: 2
D26: Layoutänderungen und Verlagerungskosten | E26: 3 | G26: 2 | H26: 2 | I26: Tim | K26: 2
C27: 3.2 Betriebskosten | K27: 2
D28: Wartung & Instandhaltung | E28: 4 | G28: 3 | H28: 3 | I28: Tim | K28: 2
D29: Energieverbrauch | E29: 4 | G29: 3 | H29: 2 | I29: Hannes | K29: 2
D30: Abschreibungen | E30: 3 | G30: 3 | H30: 3 | K30: 2
D31: Werkzeug- und Vorrichtungskosten | E31: 3 | G31: 3 | H31: 3 | K31: 2
B32: 4. Produktionslayout & Logistikkosten | K32: 1
C33: Der Materialfluss ist ein wesentlicher Treiber für Prozesskosten. | K33: 1
C34: Anpassung der Produktionsflächen | E34: 3 | G34: 3 | H34: 3 | K34: 1
C35: Optimierung Anlagenauslastung | E35: 5 | G35: 3 | H35: 3 | I35: Damir | K35: 2
C36: Kosten für Neuplanung & -installation von Materialfluss-Systemen | E36: 3 | G36: 3 | H36: 3 | K36: 1
C37: Kosten für automatische Transportsysteme (z. B. FTF/AGV) | E37: 3 | G37: 3 | H37: 3 | K37: 1
C38: Wegstreckenoptimierung (Arbeitszeit, Bewegung, Transportmittel) | K38: 1
C39: Verpackungs- und Handlingkosten | E39: 3 | G39: 3 | H39: 3 | K39: 1
C40: Rüstaufwand | E40: 2 | G40: 4 | H40: 4 | I40: Uwe, Harald | K40: 1
...

Sheet Checkliste_Prozesskosten
A1: Kostenkategorie | B1: Checkpunkt | C1: Status | D1: Bemerkungen
A2: Personalkosten | B2: Personalkapazitäten analysiert
A3: Personalkosten | B3: Qualifizierungsbedarf bewertet
A4: Personalkosten | B4: Kosten für Schichtmodelle geprüft
A5: Materialkosten | B5: Materialverfügbarkeit geprüft
A6: Materialkosten | B6: Ausschuss- & Nacharbeitskosten bewertet
A7: Maschinen/Anlagen | B7: Maschinenstundensätze hinterlegt
A8: Maschinen/Anlagen | B8: Instandhaltungsstrategie bewertet
A9: Maschinen/Anlagen | B9: Energieverbrauch analysiert
A10: Layout & Logistik | B10: Transportwege bewertet
A11: Layout & Logistik | B11: Flächenbedarf geprüft
A12: Layout & Logistik | B12: Materialfluss optimiert
A13: IT & Digitalisierung | B13: Digitalisierungsgrad bewertet
... A24: Finanzen | B24: Fördermöglichkeiten geprüft
A26: Kategorie | B26: Checkpunkt | C26: Status (Offen / In Arbeit / Fertig) | D26: Bemerkungen
A27: Prozessaufnahme | B27: Prozessschritte vollständig dokumentiert
A28: Prozessaufnahme | B28: Zeitdaten vollständig (Bearb./Rüst/Stör/Warte)
A29: Prozessaufnahme | B29: Materialflüsse erfasst (Layout, Wege, Handling)
A30: Kostenanalyse | B30: Personalkosten geprüft
A31: Kostenanalyse | B31: Maschinenstundensätze hinterlegt
A32: Kostenanalyse | B32: Gemeinkostenverteilung abgestimmt
A33: Datenqualität | B33: Zeitangaben plausibel
A34: Datenqualität | B34: Kostenangaben konsistent
A35: Optimierungspotenziale | B35: Hauptkostentreiber identifiziert
A36: Optimierungspotenziale | B36: Vorher-Nachher-Effekt berechnet
A37: Risiken | B37: Projektrisiken bewertet
A38: Risiken | B38: Bottlenecks berücksichtigt
... A40: Reporting | B40: Management-Zusammenfassung enthalten

Sheet NVH_Prozessdaten
B1: ProzessAnalyse
B3: Prozessdaten | C3: NVH
B4: Prozesse | C4: Tiefziehproduktion 01 | D4: Schäumen 02 | E4: Hinterschäumen 03 | F4: Tandemproduktion 04
B5: Volumen / Kapazität
B6: Auslastungen
B7: Prozessschritte
B8: Beschreibung
B9: Wertschöpfend (Ja/Nein)
B10: Bearbeitungszeit (s)
B11: Rüstzeit (min)
B12: Transportzeit (s)
B13: Wartezeit (s)
B14: Stillstandszeit (min)
B15: Menge/Stückzahl

Sheet 01_Analyse_Tiefzieh
B2: Tiefziehproduktion 01
B3: Prozessschritt | C3: Kosten gesamt €/Stk | D3: Hauptkostentreiber | E3: Optimierungspotenzial (%)
B4: Bestückung HL-Rolle
B5: Einfädeln HL-Rolle
B6: Aufheizen
B7: Ablängen
B8: Tiefziehen
B23: Eingabefelder

Sheet 01_Kosten_Tiefzieh
B1: Tiefziehproduktion 01
B2: Volumen / Monat
B3: Prozessschritt | C3: Personalkosten €/h | D3: Maschinenstundensatz € | E3: Materialkosten €/Stk | F3: Qualitätskosten €/Stk | G3: Logistikkosten €/Stk | H3: Gemeinkosten €
B4: =+'01_Analyse_Tiefzieh'!B4 -> Bestückung HL-Rolle
B5: =+'01_Analyse_Tiefzieh'!B5 -> Einfädeln HL-Rolle
B6: =+'01_Analyse_Tiefzieh'!B6 -> Aufheizen
B7: =+'01_Analyse_Tiefzieh'!B7 -> Ablängen
B8: =+'01_Analyse_Tiefzieh'!B8 -> Tiefziehen
B23: Übernahmefeld

Sheet 01_Vorher_Nachher
B2: Tiefziehproduktion 01 - Beispieldarstellung
B3: Prozessbereich | C3: Kosten_Vorher | D3: Kosten_Nachher
B4: Bearbeitung | C4: 0.85 | D4: 0.78
B5: Rüsten | C5: 0.42 | D5: 0.23
B6: Transport | C6: 0.18 | D6: 0.11
B7: Qualität | C7: 0.24 | D7: 0.19
B8: Nacharbeit | C8: 0.52 | D8: 0.28
B9: Instandhaltung | C9: 0.37 | D9: 0.29
B10: Gemeinkosten | C10: 0.31 | D10: 0.27

Sheet Kostenfaktoren
B1: Kostenkategorie | C1: Checkpunkt | D1: Status | E1: Bemerkungen
B2: Personalkosten | C2: Personalkapazitäten analysiert
B3: Personalkosten | C3: Qualifizierungsbedarf bewertet
B4: Personalkosten | C4: Kosten für Schichtmodelle geprüft
B5: Materialkosten | C5: Materialverfügbarkeit geprüft
B6: Materialkosten | C6: Ausschuss- & Nacharbeitskosten bewertet
B7: Maschinen/Anlagen | C7: Maschinenstundensätze hinterlegt
B8: Maschinen/Anlagen | C8: Instandhaltungsstrategie bewertet
B9: Maschinen/Anlagen | C9: Energieverbrauch analysiert
B10: Layout & Logistik | C10: Transportwege bewertet
B11: Layout & Logistik | C11: Flächenbedarf geprüft
B12: Layout & Logistik | C12: Materialfluss optimiert
B13: IT & Digitalisierung | C13: Digitalisierungsgrad bewertet
... B24: Finanzen | C24: Fördermöglichkeiten geprüft
